Workbook

Sheet README
A1: This sheet provides basic information on how to use the data template for the CIC seminar "Advanced topics in seasonal adjustment".
A2: Please read it carefully and follow the instructions below as the usage of this template is mandatory for sharing country-specific data to be used during the seminar.
A3: Please note that by providing your data you automatically agree to the inclusion of your data into the course material that will be disseminated to all participants at the end of the seminar.
A4: The deadline for data provision is five working days before the start of the seminar.
A6: Monthly time series
A7: Please use this sheet to provide up to five monthly time series of your country. To this end,
B8: - replace the preliminary country in cells B1 to F1 with the name of your country,
B9: - replace the preliminary titles in cells B2 to F2 with clear and concise titles, and
B10: - provide the respective observations in columns B to F, taking into account the dates given in column A.
A11: Your monthly time series may have different starting dates and contain missing values. However, please ensure that each series contains at least 36 observations as in general series
A12: shorter than three years will not be considered candidates for seasonal adjustment during the seminar. Also, please use the same decimal and thousand separators for all series.
A14: Quarterly time series
A15: Please use this sheet to provide up to five quarterly time series of your country. To this end,
B16: - replace the preliminary titles in cells B2 to F2 with clear and concise titles, and
B17: - provide the respective observations in columns B to F, taking into account the dates given in column A (where Jan refers to Q1, Apr to Q2, etc.).
A18: Your quarterly time series may have different starting dates and contain missing values. However, please ensure that each series contains at least 12 observations as in general series
A19: shorter than three years will not be considered candidates for seasonal adjustment during the seminar. Also, please use the same decimal and thousand separators for all series.
A21: Daily time series
A22: Please use this sheet to provide up to five daily time series of your country. To this end,
B23: - replace the preliminary titles in cells B2 to F2 with clear and concise titles, and
B24: - provide the respective observations in columns B to F, taking into account the dates given in column A.
A25: Your daily time series may have different starting dates and contain missing values. However, please ensure that each series contains at least 1100 observations as in general series
A26: shorter than three years will not be considered candidates for seasonal adjustment during the seminar. Also, please use the same decimal and thousand separators for all series.
A28: Metadata
A29: Please use this sheet to provide any additional background information about your data. This is of course optional but usually warmly welcomed by both lecturers and other participants.
A30: The background information may include
B31: - a longer and more detailed time series title,
B32: - information about data compilation,
B33: - information about events which may introduce outliers to your data, or
B34: - any difficulties you may have encountered during past seasonal adjustments of your data.
A35: Please note that you do not need to write full sentences here. Bullet points are sufficient.

Sheet Monthly time series
B1: South Korea
A2: Date | B2: CCSI | C2: CBSI(All industries) | D2: CBSI(Manufacturing) | E2: CBSI(Non-manufacturing) | F2: ESI
A3: 32874
A4: 32905
A5: 32933
A6: 32964
A7: 32994
A8: 33025
A9: 33055
A10: 33086
A11: 33117
A12: 33147
A13: 33178
A14: 33208
... A158: 37591
A159: 37622 | C159: 104.5 | D159: 104.2 | E159: 105.5 | F159: 101.6
A160: 37653 | C160: 94.9 | D160: 99.5 | E160: 92.1 | F160: 102.9
A161: 37681 | C161: 90.1 | D161: 94.9 | E161: 87 | F161: 92.6
A162: 37712 | C162: 95.3 | D162: 98.6 | E162: 93.5 | F162: 98.4
A163: 37742 | C163: 94.1 | D163: 93.8 | E163: 94.9 | F163: 96.9
A164: 37773 | C164: 91.5 | D164: 87.9 | E164: 94.9 | F164: 93.6
A165: 37803 | C165: 87.3 | D165: 82 | E165: 91.8 | F165: 93.2
A166: 37834 | C166: 89 | D166: 84.3 | E166: 93 | F166: 99.3
A167: 37865 | C167: 89 | D167: 89.6 | E167: 89 | F167: 99.8
A168: 37895 | C168: 96.2 | D168: 97.7 | E168: 95.7 | F168: 99.5
A169: 37926 | C169: 101.5 | D169: 103.4 | E169: 100.7 | F169: 103.6
A170: 37956 | C170: 103.1 | D170: 103 | E170: 103.9 | F170: 103.6
... A224: 39600 | C224: 102 | D224: 103.7 | E224: 101.4 | F224: 99.3
A225: 39630 | B225: 73.7 | C225: 99.7 | D225: 103.5 | E225: 97.4 | F225: 93.8
A226: 39661 | B226: 92.3 | C226: 100.1 | D226: 99.3 | E226: 101.4 | F226: 102.4
A227: 39692 | B227: 91 | C227: 96.3 | D227: 94.5 | E227: 98.4 | F227: 98.5
A228: 39722 | B228: 78.2 | C228: 84.3 | D228: 86.8 | E228: 82.8 | F228: 82.7
A229: 39753 | B229: 73.2 | C229: 75.7 | D229: 72.3 | E229: 78.9 | F229: 71.4
A230: 39783 | B230: 68 | C230: 68.6 | D230: 57.9 | E230: 77.7 | F230: 61.2
A231: 39814 | B231: 75.3 | C231: 70.3 | D231: 62.8 | E231: 76.8 | F231: 68
A232: 39845 | B232: 77 | C232: 70.8 | D232: 62.1 | E232: 78.2 | F232: 70.6
A233: 39873 | B233: 73.3 | C233: 77.9 | D233: 73.8 | E233: 81.7 | F233: 73.4
A234: 39904 | B234: 93.9 | C234: 92.9 | D234: 85.8 | E234: 99.3 | F234: 91.1
A235: 39934 | B235: 105.2 | C235: 97 | D235: 92.3 | E235: 101.6 | F235: 96.3
A236: 39965 | B236: 107.8 | C236: 101.6 | D236: 95.6 | E236: 107.2 | F236: 99.4
...

Sheet Quarterly time series
B1: ='Monthly time series'!B1:F1 -> South Korea
A2: Date | B2: CPI (Quaterly, 2020=100) | C2: Export Value Indices(2020=100) | D2: Export Volume Indices(2020=100) | E2: Gross domestic product at market prices(GDP) | F2: House Sales Price Index(Apartment, Quarterly)
A3: 32874 | B3: 37.264 | C3: 11.01 | D3: 6.14 | E3: 112243.3
A4: 32964 | B4: 38.368 | C4: 12.36 | D4: 6.89 | E4: 121470.2
A5: 33055 | B5: 38.932 | C5: 13.15 | D5: 7.34 | E5: 126884.6
A6: 33147 | B6: 39.355 | C6: 13.55 | D6: 7.59 | E6: 135140.2
A7: 33239 | B7: 40.894 | C7: 11.92 | D7: 6.64 | E7: 125104
A8: 33329 | B8: 41.766 | C8: 14.07 | D8: 7.79 | E8: 135935.2
A9: 33420 | B9: 42.562 | C9: 13.22 | D9: 7.3 | E9: 139327.7
A10: 33512 | B10: 43.062 | C10: 15.25 | D10: 8.38 | E10: 149282.7
A11: 33604 | B11: 43.819 | C11: 13.07 | D11: 7.21 | E11: 136078.5
A12: 33695 | B12: 44.692 | C12: 15 | D12: 8.32 | E12: 146617.3
A13: 33786 | B13: 45.128 | C13: 14.67 | D13: 8.13 | E13: 146377.9
A14: 33878 | B14: 45.102 | C14: 15.66 | D14: 8.69 | E14: 155487.4
... A58: 37895 | B58: 70.561 | C58: 44.47 | D58: 37.64 | E58: 311272.9
A59: 37987 | B59: 71.613 | C59: 44.89 | D59: 36.39 | E59: 288233.2 | F59: 59.131134
A60: 38078 | B60: 72.14 | C60: 48.92 | D60: 38.71 | E60: 306141.9 | F60: 59.633237
A61: 38169 | B61: 72.981 | C61: 47.94 | D61: 36.91 | E61: 305087.6 | F61: 59.370662
A62: 38261 | B62: 72.939 | C62: 53.11 | D62: 39.29 | E62: 321785.9 | F62: 58.938613
A63: 38353 | B63: 73.941 | C63: 50.74 | D63: 36.89 | E63: 297182.9 | F63: 58.873112
A64: 38443 | B64: 74.288 | C64: 53.43 | D64: 38.85 | E64: 318189 | F64: 60.198995
A65: 38534 | B65: 74.686 | C65: 54.83 | D65: 40.76 | E65: 320383.7 | F65: 61.708561
A66: 38626 | B66: 74.735 | C66: 59.11 | D66: 44.45 | E66: 338717.8 | F66: 61.996234
A67: 38718 | B67: 75.48 | C67: 56.47 | D67: 43.02 | E67: 315998.6 | F67: 62.776218
A68: 38808 | B68: 75.951 | C68: 60.98 | D68: 46.12 | E68: 333862.6 | F68: 64.507595
A69: 38899 | B69: 76.571 | C69: 64.11 | D69: 47.68 | E69: 336588.7 | F69: 65.362805
A70: 38991 | B70: 76.323 | C70: 66.2 | D70: 49.36 | E70: 354869.7 | F70: 68.869969
... A126: 44105 | B126: 100.2 | C126: 111.15 | D126: 108.71 | E126: 546238.3 | F126: 98.664295

Sheet Daily time series
B1: ='Monthly time series'!B1:F1 -> South Korea
A2: Date | B2: NSI | C2: KRX-KOSPI | D2: KRX-KOSDAQ | E2: Currency(won per US dollar) | F2: KORAIL-TRANSPORT-TOTAL(Daily Rail Passenger Statistics, Passengers)
A3: 40179
A4: 40180
A5: 40181
A6: 40182 | B6: =VLOOKUP(A6,[1]데이터!$A:$B,2,FALSE) -> 112.08 | C6: 1696.14 | D6: 528.09 | E6: 1167.6
A7: 40183 | B7: =VLOOKUP(A7,[1]데이터!$A:$B,2,FALSE) -> 112.47 | C7: 1690.62 | D7: 533.09 | E7: 1156.2
A8: 40184 | B8: =VLOOKUP(A8,[1]데이터!$A:$B,2,FALSE) -> 114.59 | C8: 1705.32 | D8: 539.12 | E8: 1144.3
A9: 40185 | B9: =VLOOKUP(A9,[1]데이터!$A:$B,2,FALSE) -> 116.91 | C9: 1683.45 | D9: 535.52 | E9: 1138.2
A10: 40186 | B10: =VLOOKUP(A10,[1]데이터!$A:$B,2,FALSE) -> 117.36 | C10: 1695.26 | D10: 538.96 | E10: 1133.2
A11: 40187
A12: 40188
A13: 40189 | B13: =VLOOKUP(A13,[1]데이터!$A:$B,2,FALSE) -> 116.27 | C13: 1694.12 | D13: 540.4 | E13: 1132.9
A14: 40190 | B14: =VLOOKUP(A14,[1]데이터!$A:$B,2,FALSE) -> 115.31 | C14: 1698.64 | D14: 538.11 | E14: 1119.8
A15: 40191 | B15: =VLOOKUP(A15,[1]데이터!$A:$B,2,FALSE) -> 113.63 | C15: 1671.41 | D15: 534.46 | E15: 1124.2
A16: 40192 | B16: =VLOOKUP(A16,[1]데이터!$A:$B,2,FALSE) -> 113.92 | C16: 1685.77 | D16: 542.33 | E16: 1126.4
A17: 40193 | B17: =VLOOKUP(A17,[1]데이터!$A:$B,2,FALSE) -> 116.14 | C17: 1701.8 | D17: 549.97 | E17: 1122.1
A18: 40194
A19: 40195
A20: 40196 | B20: =VLOOKUP(A20,[1]데이터!$A:$B,2,FALSE) -> 113.09 | C20: 1711.78 | D20: 553.1 | E20: 1123.2
A21: 40197 | B21: =VLOOKUP(A21,[1]데이터!$A:$B,2,FALSE) -> 112.75 | C21: 1710.22 | D21: 549.14 | E21: 1126.9
A22: 40198 | B22: =VLOOKUP(A22,[1]데이터!$A:$B,2,FALSE) -> 114.51 | C22: 1714.38 | D22: 544.12 | E22: 1124.3
A23: 40199 | B23: =VLOOKUP(A23,[1]데이터!$A:$B,2,FALSE) -> 114.29 | C23: 1722.01 | D23: 549.03 | E23: 1132.3
A24: 40200 | B24: =VLOOKUP(A24,[1]데이터!$A:$B,2,FALSE) -> 110.64 | C24: 1684.35 | D24: 546.66 | E24: 1138.5
A25: 40201
A26: 40202
A27: 40203 | B27: =VLOOKUP(A27,[1]데이터!$A:$B,2,FALSE) -> 111.51 | C27: 1670.2 | D27: 534.22 | E27: 1150.1
A28: 40204 | B28: =VLOOKUP(A28,[1]데이터!$A:$B,2,FALSE) -> 109.32 | C28: 1637.34 | D28: 522.07 | E28: 1149.1
A29: 40205 | B29: =VLOOKUP(A29,[1]데이터!$A:$B,2,FALSE) -> 108.47 | C29: 1625.48 | D29: 516.43 | E29: 1151.2
A30: 40206 | B30: =VLOOKUP(A30,[1]데이터!$A:$B,2,FALSE) -> 108.39 | C30: 1642.43 | D30: 517.4 | E30: 1159.4
A31: 40207 | B31: =VLOOKUP(A31,[1]데이터!$A:$B,2,FALSE) -> 109.69 | C31: 1602.43 | D31: 496.57 | E31: 1156.5
A32: 40208
A33: 40209
A34: 40210 | B34: =VLOOKUP(A34,[1]데이터!$A:$B,2,FALSE) -> 106.1 | C34: 1606.44 | D34: 502 | E34: 1157.9
A35: 40211 | B35: =VLOOKUP(A35,[1]데이터!$A:$B,2,FALSE) -> 107.86 | C35: 1595.81 | D35: 504.69 | E35: 1167.8
A36: 40212 | B36: =VLOOKUP(A36,[1]데이터!$A:$B,2,FALSE) -> 108.49 | C36: 1615.02 | D36: 515.32 | E36: 1160.1
A37: 40213 | B37: =VLOOKUP(A37,[1]데이터!$A:$B,2,FALSE) -> 105.87 | C37: 1616.42 | D37: 516.23 | E37: 1152.2
A38: 40214 | B38: =VLOOKUP(A38,[1]데이터!$A:$B,2,FALSE) -> 102.19 | C38: 1567.12 | D38: 497.37 | E38: 1153.3
A39: 40215
A40: 40216
...

Sheet Metadata
A1: Time series periodicity | B1: Time series title | C1: Time series information
A2: Monthly | B2: ='Monthly time series'!B2 -> CCSI | C2: Composite Consumer Sentiment Index (National Tendency)
B3: ='Monthly time series'!C2 -> CBSI(All industries) | C3: Composite Business Sentiment Index (All industries, National Tendency)
B4: ='Monthly time series'!D2 -> CBSI(Manufacturing) | C4: Composite Business Sentiment Index (Manufacturing, National Tendency)
B5: ='Monthly time series'!E2 -> CBSI(Non-manufacturing) | C5: Composite Business Sentiment Index (Non-manufacturing, National Tendency)
B6: ='Monthly time series'!F2 -> ESI | C6: Economic Sentiment Index
A7: Quarterly | B7: ='Quarterly time series'!B2 -> CPI (Quaterly, 2020=100) | C7: Consumer Price Index (Quarterly)
B8: ='Quarterly time series'!C2 -> Export Value Indices(2020=100)
B9: ='Quarterly time series'!D2 -> Export Volume Indices(2020=100)
B10: ='Quarterly time series'!E2 -> Gross domestic product at market prices(GDP)
B11: ='Quarterly time series'!F2 -> House Sales Price Index(Apartment, Quarterly) | C11: Source: Korean Real Estate Board)
A12: Daily | B12: ='Daily time series'!B2 -> NSI | C12: News Sentiment Index(experimental statistics)
B13: ='Daily time series'!C2 -> KRX-KOSPI
B14: ='Daily time series'!D2 -> KRX-KOSDAQ
B15: ='Daily time series'!E2 -> Currency(won per US dollar)
B16: ='Daily time series'!F2 -> KORAIL-TRANSPORT-TOTAL(Daily Rail Passenger Statistics, Passengers) | C16: Daily Rail Passenger Statistics, Number of Passengers
